Workbook

Sheet VLANs
A1: VLAN | B1: Subnet | C1: Mascara | D1: Gateway | E1: Descripcion
A2: 2011 | B2: 10.150.11.0/24 | C2: 255.255.255.0 | D2: 10.150.11.254
A3: 2012 | B3: 10.150.12.0/24 | C3: 255.255.255.0 | D3: 10.150.12.254
A4: 3000 | B4: 10.150.0.0/26 | C4: 255.255.255.192 | D4: 10.150.0.62
A5: 3001 | B5: 10.150.0.64/26 | C5: 255.255.255.192 | D5: 10.150.0.126
A6: 3002 | B6: 10.150.0.128/26 | C6: 255.255.255.192 | D6: 10.150.0.190
A7: 3003 | B7: 10.150.0.192/26 | C7: 255.255.255.192 | D7: 10.150.0.254
A8: 3004 | B8: 10.150.1.0/26 | C8: 255.255.255.192 | D8: 10.150.1.62
A9: 3005 | B9: 10.150.1.64/26 | C9: 255.255.255.192 | D9: 10.150.1.126
A10: 3006 | B10: 10.150.1.128/26 | C10: 255.255.255.192 | D10: 10.150.1.190
A11: 3007 | B11: 10.150.2.0/26 | C11: 255.255.255.192 | D11: 10.150.2.62
A12: 3008 | B12: 10.150.2.64/26 | C12: 255.255.255.192 | D12: 10.150.2.126
A13: 3009 | B13: 10.150.2.128/26 | C13: 255.255.255.192 | D13: 10.150.2.190
... A38: 3334 | B38: 10.150.3.192/26 | C38: 255.255.255.192 | D38: 10.150.3.254

Sheet Servidores
A1: Host | B1: Descripcion | C1: Ambiente | D1: Cluster | E1: IP | F1: VLAN | G1: Subnet | H1: Gateway | I1: Mascara | J1: Observaciones
A2: ADCPF5LTMDMZ02 | B2: F5 DMZ QA | C2: QA | D2: VDCPVCAOTCLPR10 | E2: 10.150.5.131 | F2: 3020 | G2: =VLOOKUP(F2,VLANs!A:E,2,FALSE) -> 10.150.5.128/26 | H2: =VLOOKUP(F2,VLANs!A:E,4,FALSE) -> 10.150.5.190 | I2: =VLOOKUP(F2,VLANs!A:E,3,FALSE) -> 255.255.255.192
A3: ADCPF5LTMDMZ02 | B3: F5 DMZ QA | C3: QA | D3: VDCPVCAOTCLPR10 | E3: 10.150.7.87 | F3: 3027 | G3: =VLOOKUP(F3,VLANs!A:E,2,FALSE) -> 10.150.7.64/26 | H3: =VLOOKUP(F3,VLANs!A:E,4,FALSE) -> 10.150.7.126 | I3: =VLOOKUP(F3,VLANs!A:E,3,FALSE) -> 255.255.255.192
A4: ADCPF5LTMLBPR02 | B4: F5 | C4: PROD | D4: VDCPVCAOTCLPR10 | E4: 10.150.1.194 | F4: 3333 | G4: =VLOOKUP(F4,VLANs!A:E,2,FALSE) -> 10.150.1.192/26 | H4: =VLOOKUP(F4,VLANs!A:E,4,FALSE) -> 10.150.1.254 | I4: =VLOOKUP(F4,VLANs!A:E,3,FALSE) -> 255.255.255.192
A5: ADCPF5LTMLBPR02 | B5: F5 | C5: PROD | D5: VDCPVCAOTCLPR10 | E5: 10.150.2.122 | F5: 3008 | G5: =VLOOKUP(F5,VLANs!A:E,2,FALSE) -> 10.150.2.64/26 | H5: =VLOOKUP(F5,VLANs!A:E,4,FALSE) -> 10.150.2.126 | I5: =VLOOKUP(F5,VLANs!A:E,3,FALSE) -> 255.255.255.192
A6: ADCPF5LTMLBPR02 | C6: PROD | D6: VDCPVCAOTCLPR10 | E6: 10.150.8.102 | F6: 3030 | G6: =VLOOKUP(F6,VLANs!A:E,2,FALSE) -> 10.150.8.0/24 | H6: =VLOOKUP(F6,VLANs!A:E,4,FALSE) -> 10.150.8.254 | I6: =VLOOKUP(F6,VLANs!A:E,3,FALSE) -> 255.255.255.0
A7: ADCPF5LTMLBQA02 | B7: F5 | C7: QA | D7: VDCPVCAOTCLPR10 | E7: 10.150.1.196 | F7: 3333 | G7: =VLOOKUP(F7,VLANs!A:E,2,FALSE) -> 10.150.1.192/26 | H7: =VLOOKUP(F7,VLANs!A:E,4,FALSE) -> 10.150.1.254 | I7: =VLOOKUP(F7,VLANs!A:E,3,FALSE) -> 255.255.255.192
A8: ADCPF5LTMLBQA02 | B8: F5 | C8: QA | D8: VDCPVCAOTCLPR10 | E8: 10.150.4.6 | F8: 3014 | G8: =VLOOKUP(F8,VLANs!A:E,2,FALSE) -> 10.150.4.0/26 | H8: =VLOOKUP(F8,VLANs!A:E,4,FALSE) -> 10.150.4.62 | I8: =VLOOKUP(F8,VLANs!A:E,3,FALSE) -> 255.255.255.192
A9: ADCPF5LTMLBQA02 | C9: QA | D9: VDCPVCAOTCLPR10 | E9: 10.150.9.6 | F9: 3031 | G9: =VLOOKUP(F9,VLANs!A:E,2,FALSE) -> 10.150.9.0/24 | H9: =VLOOKUP(F9,VLANs!A:E,4,FALSE) -> 10.150.9.254 | I9: =VLOOKUP(F9,VLANs!A:E,3,FALSE) -> 255.255.255.0
A10: ATROF5LTMDMZ01 | C10: PROD | D10: VDCPVCAOTCLPR10 | E10: 10.150.5.68 | F10: 3019 | G10: =VLOOKUP(F10,VLANs!A:E,2,FALSE) -> 10.150.5.64/26 | H10: =VLOOKUP(F10,VLANs!A:E,4,FALSE) -> 10.150.5.126 | I10: =VLOOKUP(F10,VLANs!A:E,3,FALSE) -> 255.255.255.192
A11: ATROF5LTMDMZ01 | B11: F5 | C11: PROD | D11: VDCPVCAOTCLPR10 | E11: 10.150.6.67 | F11: 3023 | G11: =VLOOKUP(F11,VLANs!A:E,2,FALSE) -> 10.150.6.64/26 | H11: =VLOOKUP(F11,VLANs!A:E,4,FALSE) -> 10.150.6.126 | I11: =VLOOKUP(F11,VLANs!A:E,3,FALSE) -> 255.255.255.192
A12: ATROF5LTMDMZ01 | B12: F5 DMZ QA | C12: QA | D12: VDCPVCAOTCLPR10 | E12: 10.150.7.86 | F12: 3027 | G12: =VLOOKUP(F12,VLANs!A:E,2,FALSE) -> 10.150.7.64/26 | H12: =VLOOKUP(F12,VLANs!A:E,4,FALSE) -> 10.150.7.126 | I12: =VLOOKUP(F12,VLANs!A:E,3,FALSE) -> 255.255.255.192
A13: ATROF5LTMDMZ01 | B13: F5 DMZ QA | C13: QA | D13: VDCPVCAOTCLPR10 | E13: 10.150.5.130 | F13: 3020 | G13: =VLOOKUP(F13,VLANs!A:E,2,FALSE) -> 10.150.5.128/26 | H13: =VLOOKUP(F13,VLANs!A:E,4,FALSE) -> 10.150.5.190 | I13: =VLOOKUP(F13,VLANs!A:E,3,FALSE) -> 255.255.255.192
A14: ATROF5LTMDMZ02 | B14: F5 DMZ PR | C14: PROD | D14: VDCPVCAOTCLPR10 | E14: 10.150.5.80 | F14: 3019 | G14: =VLOOKUP(F14,VLANs!A:E,2,FALSE) -> 10.150.5.64/26 | H14: =VLOOKUP(F14,VLANs!A:E,4,FALSE) -> 10.150.5.126 | I14: =VLOOKUP(F14,VLANs!A:E,3,FALSE) -> 255.255.255.192
A15: ATROF5LTMDMZ02 | B15: F5 | C15: PROD | D15: VDCPVCAOTCLPR10 | E15: 10.150.6.68 | F15: 3023 | G15: =VLOOKUP(F15,VLANs!A:E,2,FALSE) -> 10.150.6.64/26 | H15: =VLOOKUP(F15,VLANs!A:E,4,FALSE) -> 10.150.6.126 | I15: =VLOOKUP(F15,VLANs!A:E,3,FALSE) -> 255.255.255.192
A16: ATROF5LTMDMZ02 | B16: es Un nateo, que va de la 10.150.2.78 --> 10.150.6.80 | C16: PROD | D16: VDCPVCAOTCLPR10 | E16: 10.150.6.80 | F16: 3023 | G16: =VLOOKUP(F16,VLANs!A:E,2,FALSE) -> 10.150.6.64/26 | H16: =VLOOKUP(F16,VLANs!A:E,4,FALSE) -> 10.150.6.126 | I16: =VLOOKUP(F16,VLANs!A:E,3,FALSE) -> 255.255.255.192
A17: ATROF5LTMLBPR01 | B17: F5 | C17: PROD | D17: VDCPVCAOTCLPR10 | E17: 10.150.1.193 | F17: 3333 | G17: =VLOOKUP(F17,VLANs!A:E,2,FALSE) -> 10.150.1.192/26 | H17: =VLOOKUP(F17,VLANs!A:E,4,FALSE) -> 10.150.1.254 | I17: =VLOOKUP(F17,VLANs!A:E,3,FALSE) -> 255.255.255.192
A18: ATROF5LTMLBPR01 | B18: Balanceador | C18: PROD | D18: VDCPVCAOTCLPR10 | E18: 10.150.2.11 | F18: 3007 | G18: =VLOOKUP(F18,VLANs!A:E,2,FALSE) -> 10.150.2.0/26 | H18: =VLOOKUP(F18,VLANs!A:E,4,FALSE) -> 10.150.2.62 | I18: =VLOOKUP(F18,VLANs!A:E,3,FALSE) -> 255.255.255.192
A19: ATROF5LTMLBPR01 | B19: F5 | C19: PROD | D19: VDCPVCAOTCLPR10 | E19: 10.150.5.21 | F19: 3018 | G19: =VLOOKUP(F19,VLANs!A:E,2,FALSE) -> 10.150.5.0/26 | H19: =VLOOKUP(F19,VLANs!A:E,4,FALSE) -> 10.150.5.62 | I19: =VLOOKUP(F19,VLANs!A:E,3,FALSE) -> 255.255.255.192
A20: ATROF5LTMLBPR01 | C20: PROD | D20: VDCPVCAOTCLPR10 | E20: 10.150.8.101 | F20: 3030 | G20: =VLOOKUP(F20,VLANs!A:E,2,FALSE) -> 10.150.8.0/24 | H20: =VLOOKUP(F20,VLANs!A:E,4,FALSE) -> 10.150.8.254 | I20: =VLOOKUP(F20,VLANs!A:E,3,FALSE) -> 255.255.255.0
A21: ATROF5LTMLBPR02 | B21: F5 | C21: PROD | D21: VDCPVCAOTCLPR10 | E21: 10.150.5.22 | F21: 3018 | G21: =VLOOKUP(F21,VLANs!A:E,2,FALSE) -> 10.150.5.0/26 | H21: =VLOOKUP(F21,VLANs!A:E,4,FALSE) -> 10.150.5.62 | I21: =VLOOKUP(F21,VLANs!A:E,3,FALSE) -> 255.255.255.192
A22: ATROF5LTMLBQA01 | B22: F5 | C22: QA | D22: VDCPVCAOTCLPR10 | E22: 10.150.1.195 | F22: 3333 | G22: =VLOOKUP(F22,VLANs!A:E,2,FALSE) -> 10.150.1.192/26 | H22: =VLOOKUP(F22,VLANs!A:E,4,FALSE) -> 10.150.1.254 | I22: =VLOOKUP(F22,VLANs!A:E,3,FALSE) -> 255.255.255.192
A23: ATROF5LTMLBQA01 | B23: F5 | C23: QA | D23: VDCPVCAOTCLPR10 | E23: 10.150.4.4 | F23: 3014 | G23: =VLOOKUP(F23,VLANs!A:E,2,FALSE) -> 10.150.4.0/26 | H23: =VLOOKUP(F23,VLANs!A:E,4,FALSE) -> 10.150.4.62 | I23: =VLOOKUP(F23,VLANs!A:E,3,FALSE) -> 255.255.255.192
A24: ATROF5LTMLBQA01 | C24: QA | D24: VDCPVCAOTCLPR10 | E24: 10.150.9.4 | F24: 3031 | G24: =VLOOKUP(F24,VLANs!A:E,2,FALSE) -> 10.150.9.0/24 | H24: =VLOOKUP(F24,VLANs!A:E,4,FALSE) -> 10.150.9.254 | I24: =VLOOKUP(F24,VLANs!A:E,3,FALSE) -> 255.255.255.0
A25: ATROQUALYGWPR01 | B25: Qualys | C25: PROD | D25: VDCPVCAOTCLPR10 | E25: 10.150.5.110 | F25: 3019 | G25: =VLOOKUP(F25,VLANs!A:E,2,FALSE) -> 10.150.5.64/26 | H25: =VLOOKUP(F25,VLANs!A:E,4,FALSE) -> 10.150.5.126 | I25: =VLOOKUP(F25,VLANs!A:E,3,FALSE) -> 255.255.255.192
A26: F5VIRTUALAP-QA | B26: Interfaz F5 Red OT-QA-F5 | C26: QA | D26: VDCPVCAOTCLPR10 | E26: 10.150.9.1 | F26: 3031 | G26: =VLOOKUP(F26,VLANs!A:E,2,FALSE) -> 10.150.9.0/24 | H26: =VLOOKUP(F26,VLANs!A:E,4,FALSE) -> 10.150.9.254 | I26: =VLOOKUP(F26,VLANs!A:E,3,FALSE) -> 255.255.255.0
A27: LDCPCLIQCAPOT01 | C27: PROD | D27: VDCPVCAOTCLPR10 | E27: 10.150.5.84 | F27: 3019 | G27: =VLOOKUP(F27,VLANs!A:E,2,FALSE) -> 10.150.5.64/26 | H27: =VLOOKUP(F27,VLANs!A:E,4,FALSE) -> 10.150.5.126 | I27: =VLOOKUP(F27,VLANs!A:E,3,FALSE) -> 255.255.255.192
A28: LDCPCMTFAPPP02 | B28: IDMS-MT PP - Cirion | C28: QA | D28: VDCPVCAOTCLPR10 | E28: 10.150.4.229 | F28: 3017 | G28: =VLOOKUP(F28,VLANs!A:E,2,FALSE) -> 10.150.4.192/26 | H28: =VLOOKUP(F28,VLANs!A:E,4,FALSE) -> 10.150.4.254 | I28: =VLOOKUP(F28,VLANs!A:E,3,FALSE) -> 255.255.255.192
A29: LDCPCMTFAPPR02 | B29: IDMS-MT PROD - Cirion | C29: PROD | D29: VDCPVCAOTCLPR10 | E29: 10.150.2.217 | F29: 3010 | G29: =VLOOKUP(F29,VLANs!A:E,2,FALSE) -> 10.150.2.192/26 | H29: =VLOOKUP(F29,VLANs!A:E,4,FALSE) -> 10.150.2.254 | I29: =VLOOKUP(F29,VLANs!A:E,3,FALSE) -> 255.255.255.192
A30: LDCPCMTFAPQA02 | B30: IDMS-MT QA - Cirion | C30: QA | D30: VDCPVCAOTCLPR10 | E30: 10.150.4.221 | F30: 3017 | G30: =VLOOKUP(F30,VLANs!A:E,2,FALSE) -> 10.150.4.192/26 | H30: =VLOOKUP(F30,VLANs!A:E,4,FALSE) -> 10.150.4.254 | I30: =VLOOKUP(F30,VLANs!A:E,3,FALSE) -> 255.255.255.192
A31: LDCPCMTIAPPP02 | B31: Interfaz Despacho MT-PP Cirion | C31: QA | D31: VDCPVCAOTCLPR10 | E31: 10.150.7.105 | F31: 3027 | G31: =VLOOKUP(F31,VLANs!A:E,2,FALSE) -> 10.150.7.64/26 | H31: =VLOOKUP(F31,VLANs!A:E,4,FALSE) -> 10.150.7.126 | I31: =VLOOKUP(F31,VLANs!A:E,3,FALSE) -> 255.255.255.192
A32: LDCPCMTIAPPR02 | B32: Interfaz Despacho MT-PR Cirion | C32: PROD | D32: VDCPVCAOTCLPR10 | E32: 10.150.6.103 | F32: 3023 | G32: =VLOOKUP(F32,VLANs!A:E,2,FALSE) -> 10.150.6.64/26 | H32: =VLOOKUP(F32,VLANs!A:E,4,FALSE) -> 10.150.6.126 | I32: =VLOOKUP(F32,VLANs!A:E,3,FALSE) -> 255.255.255.192
A33: LDCPCMTIAPQA02 | B33: Interfaz Despacho MT-QA Cirion | C33: QA | D33: VDCPVCAOTCLPR10 | E33: 10.150.7.107 | F33: 3027 | G33: =VLOOKUP(F33,VLANs!A:E,2,FALSE) -> 10.150.7.64/26 | H33: =VLOOKUP(F33,VLANs!A:E,4,FALSE) -> 10.150.7.126 | I33: =VLOOKUP(F33,VLANs!A:E,3,FALSE) -> 255.255.255.192
A34: LDCPCMTISAPPP02 | B34: Interfaz SCADA-MT PP - Cirion | C34: QA | D34: VDCPVCAOTCLPR10 | E34: 10.150.4.235 | F34: 3017 | G34: =VLOOKUP(F34,VLANs!A:E,2,FALSE) -> 10.150.4.192/26 | H34: =VLOOKUP(F34,VLANs!A:E,4,FALSE) -> 10.150.4.254 | I34: =VLOOKUP(F34,VLANs!A:E,3,FALSE) -> 255.255.255.192
A35: LDCPCMTISAPPR02 | B35: Interfaz SCADA-MT PROD - Cirion | C35: PROD | D35: VDCPVCAOTCLPR10 | E35: 10.150.2.221 | F35: 3010 | G35: =VLOOKUP(F35,VLANs!A:E,2,FALSE) -> 10.150.2.192/26 | H35: =VLOOKUP(F35,VLANs!A:E,4,FALSE) -> 10.150.2.254 | I35: =VLOOKUP(F35,VLANs!A:E,3,FALSE) -> 255.255.255.192
A36: LDCPCMTISAPQA02 | B36: Interfaz SCADA-MT QA - Cirion | C36: QA | D36: VDCPVCAOTCLPR10 | E36: 10.150.4.227 | F36: 3017 | G36: =VLOOKUP(F36,VLANs!A:E,2,FALSE) -> 10.150.4.192/26 | H36: =VLOOKUP(F36,VLANs!A:E,4,FALSE) -> 10.150.4.254 | I36: =VLOOKUP(F36,VLANs!A:E,3,FALSE) -> 255.255.255.192
A37: LDCPCMTSAPPP02 | B37: Cromo Red - MT PP - Cirion | C37: QA | D37: VDCPVCAOTCLPR10 | E37: 10.150.4.233 | F37: 3017 | G37: =VLOOKUP(F37,VLANs!A:E,2,FALSE) -> 10.150.4.192/26 | H37: =VLOOKUP(F37,VLANs!A:E,4,FALSE) -> 10.150.4.254 | I37: =VLOOKUP(F37,VLANs!A:E,3,FALSE) -> 255.255.255.192
A38: LDCPCMTSAPPR02 | B38: Cromo Red - MT PROD - Cirion | C38: PROD | D38: VDCPVCAOTCLPR10 | E38: 10.150.2.219 | F38: 3010 | G38: =VLOOKUP(F38,VLANs!A:E,2,FALSE) -> 10.150.2.192/26 | H38: =VLOOKUP(F38,VLANs!A:E,4,FALSE) -> 10.150.2.254 | I38: =VLOOKUP(F38,VLANs!A:E,3,FALSE) -> 255.255.255.192
A39: LDCPCMTSAPQA02 | B39: Cromo Red - MT QA - Cirion | C39: QA | D39: VDCPVCAOTCLPR10 | E39: 10.150.4.225 | F39: 3017 | G39: =VLOOKUP(F39,VLANs!A:E,2,FALSE) -> 10.150.4.192/26 | H39: =VLOOKUP(F39,VLANs!A:E,4,FALSE) -> 10.150.4.254 | I39: =VLOOKUP(F39,VLANs!A:E,3,FALSE) -> 255.255.255.192
A40: LDCPNAGSCAPPR02 | B40: NAGIOS OT Cirion | C40: PROD | D40: VDCPVCAOTCLPR10 | E40: 10.150.5.51 | F40: 3018 | G40: =VLOOKUP(F40,VLANs!A:E,2,FALSE) -> 10.150.5.0/26 | H40: =VLOOKUP(F40,VLANs!A:E,4,FALSE) -> 10.150.5.62 | I40: =VLOOKUP(F40,VLANs!A:E,3,FALSE) -> 255.255.255.192
...

Sheet IPs_VLAN
A1: VLAN | B1: IP | C1: Estado | D1: Descripcion
A2: 2011 | B2: 10.150.11.1 | C2: =IF(COUNTIF(Servidores!E:E,B2)>0,"USADA","LIBRE") -> LIBRE
A3: 2011 | B3: 10.150.11.2 | C3: =IF(COUNTIF(Servidores!E:E,B3)>0,"USADA","LIBRE") -> LIBRE
A4: 2011 | B4: 10.150.11.3 | C4: =IF(COUNTIF(Servidores!E:E,B4)>0,"USADA","LIBRE") -> USADA
A5: 2011 | B5: 10.150.11.4 | C5: =IF(COUNTIF(Servidores!E:E,B5)>0,"USADA","LIBRE") -> USADA
A6: 2011 | B6: 10.150.11.5 | C6: =IF(COUNTIF(Servidores!E:E,B6)>0,"USADA","LIBRE") -> LIBRE
A7: 2011 | B7: 10.150.11.6 | C7: =IF(COUNTIF(Servidores!E:E,B7)>0,"USADA","LIBRE") -> LIBRE
A8: 2011 | B8: 10.150.11.7 | C8: =IF(COUNTIF(Servidores!E:E,B8)>0,"USADA","LIBRE") -> LIBRE
A9: 2011 | B9: 10.150.11.8 | C9: =IF(COUNTIF(Servidores!E:E,B9)>0,"USADA","LIBRE") -> LIBRE
A10: 2011 | B10: 10.150.11.9 | C10: =IF(COUNTIF(Servidores!E:E,B10)>0,"USADA","LIBRE") -> LIBRE
A11: 2011 | B11: 10.150.11.10 | C11: =IF(COUNTIF(Servidores!E:E,B11)>0,"USADA","LIBRE") -> LIBRE
A12: 2011 | B12: 10.150.11.11 | C12: =IF(COUNTIF(Servidores!E:E,B12)>0,"USADA","LIBRE") -> LIBRE
A13: 2011 | B13: 10.150.11.12 | C13: =IF(COUNTIF(Servidores!E:E,B13)>0,"USADA","LIBRE") -> LIBRE
... A570: 3000 | B570: 10.150.0.61 | C570: =IF(COUNTIF(Servidores!E:E,B570)>0,"USADA","LIBRE") -> LIBRE
A571: 3000 | B571: 10.150.0.62 | C571: =IF(COUNTIF(Servidores!E:E,B571)>0,"USADA","LIBRE") -> LIBRE | D571: Gateway
A572: 3000 | B572: 10.150.0.63 | C572: =IF(COUNTIF(Servidores!E:E,B572)>0,"USADA","LIBRE") -> LIBRE | D572: Broadcast
A573: 3001 | B573: 10.150.0.64 | C573: =IF(COUNTIF(Servidores!E:E,B573)>0,"USADA","LIBRE") -> LIBRE
A574: 3001 | B574: 10.150.0.65 | C574: =IF(COUNTIF(Servidores!E:E,B574)>0,"USADA","LIBRE") -> USADA
A575: 3001 | B575: 10.150.0.66 | C575: =IF(COUNTIF(Servidores!E:E,B575)>0,"USADA","LIBRE") -> USADA
A576: 3001 | B576: 10.150.0.67 | C576: =IF(COUNTIF(Servidores!E:E,B576)>0,"USADA","LIBRE") -> USADA
A577: 3001 | B577: 10.150.0.68 | C577: =IF(COUNTIF(Servidores!E:E,B577)>0,"USADA","LIBRE") -> USADA
A578: 3001 | B578: 10.150.0.69 | C578: =IF(COUNTIF(Servidores!E:E,B578)>0,"USADA","LIBRE") -> USADA
A579: 3001 | B579: 10.150.0.70 | C579: =IF(COUNTIF(Servidores!E:E,B579)>0,"USADA","LIBRE") -> LIBRE
A580: 3001 | B580: 10.150.0.71 | C580: =IF(COUNTIF(Servidores!E:E,B580)>0,"USADA","LIBRE") -> LIBRE
A581: 3001 | B581: 10.150.0.72 | C581: =IF(COUNTIF(Servidores!E:E,B581)>0,"USADA","LIBRE") -> LIBRE
A582: 3001 | B582: 10.150.0.73 | C582: =IF(COUNTIF(Servidores!E:E,B582)>0,"USADA","LIBRE") -> LIBRE
A583: 3001 | B583: 10.150.0.74 | C583: =IF(COUNTIF(Servidores!E:E,B583)>0,"USADA","LIBRE") -> LIBRE
A584: 3001 | B584: 10.150.0.75 | C584: =IF(COUNTIF(Servidores!E:E,B584)>0,"USADA","LIBRE") -> LIBRE
... A634: 3001 | B634: 10.150.0.125 | C634: =IF(COUNTIF(Servidores!E:E,B634)>0,"USADA","LIBRE") -> USADA
A635: 3001 | B635: 10.150.0.126 | C635: =IF(COUNTIF(Servidores!E:E,B635)>0,"USADA","LIBRE") -> LIBRE | D635: Gateway
A636: 3001 | B636: 10.150.0.127 | C636: =IF(COUNTIF(Servidores!E:E,B636)>0,"USADA","LIBRE") -> LIBRE | D636: Broadcast
A637: 3002 | B637: 10.150.0.128 | C637: =IF(COUNTIF(Servidores!E:E,B637)>0,"USADA","LIBRE") -> LIBRE
A638: 3002 | B638: 10.150.0.129 | C638: =IF(COUNTIF(Servidores!E:E,B638)>0,"USADA","LIBRE") -> LIBRE
A639: 3002 | B639: 10.150.0.130 | C639: =IF(COUNTIF(Servidores!E:E,B639)>0,"USADA","LIBRE") -> LIBRE
A640: 3002 | B640: 10.150.0.131 | C640: =IF(COUNTIF(Servidores!E:E,B640)>0,"USADA","LIBRE") -> LIBRE
A641: 3002 | B641: 10.150.0.132 | C641: =IF(COUNTIF(Servidores!E:E,B641)>0,"USADA","LIBRE") -> LIBRE
A642: 3002 | B642: 10.150.0.133 | C642: =IF(COUNTIF(Servidores!E:E,B642)>0,"USADA","LIBRE") -> LIBRE
A643: 3002 | B643: 10.150.0.134 | C643: =IF(COUNTIF(Servidores!E:E,B643)>0,"USADA","LIBRE") -> LIBRE
A644: 3002 | B644: 10.150.0.135 | C644: =IF(COUNTIF(Servidores!E:E,B644)>0,"USADA","LIBRE") -> LIBRE
A645: 3002 | B645: 10.150.0.136 | C645: =IF(COUNTIF(Servidores!E:E,B645)>0,"USADA","LIBRE") -> LIBRE
...
